<?xml version="1.0"?>
<robot name="UGV">
    <link name="chassis">
        <visual>
            <geometry>
                <box size="10 16 4" />
            </geometry>
        </visual>
    </link>
    <link name="front_left_wheel_body">
        <visual>
            <origin xyz="0 0 0" rpy="1.5707963267948966 0 0"/>
            <geometry>
                <cylinder radius="4" length="1" />
            </geometry>
        </visual>
    </link>
    <joint name="front_left_wheel_joint" type="revolute">
        <parent link="chassis"/>
        <child link="front_left_wheel_body"/>
        <origin xyz="5 -8.5 0" rpy="0 0 0"/>
        <axis xyz="0 1 0" />
        <limit effort="0" velocity="0" />
    </joint>
    <link name="front_right_wheel_body">
        <visual>
            <origin xyz="0 0 0" rpy="1.5707963267948966 0 0"/>
            <geometry>
                <cylinder radius="4" length="1" />
            </geometry>
        </visual>
    </link>
    <joint name="front_right_wheel_joint" type="revolute">
        <parent link="chassis"/>
        <child link="front_right_wheel_body"/>
        <origin xyz="5 8.5 0" rpy="0 0 0"/>
        <axis xyz="0 1 0" />
        <limit effort="0" velocity="0" />
    </joint>
    <link name="rear_left_wheel_body">
        <visual>
            <origin xyz="0 0 0" rpy="1.5707963267948966 0 0"/>
            <geometry>
                <cylinder radius="4" length="1" />
            </geometry>
        </visual>
    </link>
    <joint name="rear_left_wheel_joint" type="revolute">
        <parent link="chassis"/>
        <child link="rear_left_wheel_body"/>
        <origin xyz="-5 -8.5 0" rpy="0 0 0"/>
        <axis xyz="0 1 0" />
        <limit effort="0" velocity="0" />
    </joint>
    <link name="rear_right_wheel_body">
        <visual>
            <origin xyz="0 0 0" rpy="1.5707963267948966 0 0"/>
            <geometry>
                <cylinder radius="4" length="1" />
            </geometry>
        </visual>
    </link>
    <joint name="rear_right_wheel_joint" type="revolute">
        <parent link="chassis"/>
        <child link="rear_right_wheel_body"/>
        <origin xyz="-5 8.5 0" rpy="0 0 0"/>
        <axis xyz="0 1 0" />
        <limit effort="0" velocity="0" />
    </joint>
</robot>